<?xml version="1.0"?>
<robot xmlns:xacro="http://www.ros.org/wiki/xacro">


<material name="white">
    <color rgba="1 1 1 1"/>
</material>

<material name="black">
    <color rgba="0 0 0 1"/>
</material>

<material name="red">
    <color rgba="1 0 0 1"/>
</material>

<material name="green">
    <color rgba="0 1 0 1"/>
</material>

<material name="blue">
    <color rgba="0 0 1 1"/>
</material>

<material name="yellow">
    <color rgba="1 1 0 1"/>
</material>

<!-- Base Link -->

<link name="base_link">

</link>

<!-- Base Footprint-->

<joint name="base_footprint_joint" type="fixed">
    <parent link="base_link"/>
    <child link="base_footprint"/>
    <origin xyz="0 0 0" rpy="0 0 0"/>
</joint>

<link name="base_footprint">
</link>

<!-- Chassis Link -->

<joint name="chassis_joint" type="fixed">
    <parent link="base_link"/>
    <child link="chassis"/>
    <origin xyz="0 0 0" rpy="0 0 0"/>
</joint>

<link name="chassis">
    <visual>
        <origin xyz="0 0 0.075" rpy="0 0 0"/>
        <geometry>
            <box size="0.4 0.4 0.2"/>
        </geometry>
        <material name="white"/>
    </visual>
</link>

<!-- Rear Left Wheel -->

<joint name="rear_left_wheel_joint" type="continuous">
    <parent link="base_link"/>
    <child link="rear_left_wheel"/>
    <origin xyz="-0.2 0.2 0" rpy="-${pi/2} 0 0"/>
    <axis xyz="0 0 1"/>
</joint>

<link name="rear_left_wheel">
    <visual>
        <geometry>
            <cylinder radius="0.05" length="0.04"/>
        </geometry>
        <material name="blue"/>
    </visual>
</link>

<!-- Rear Right Wheel -->

<joint name="rear_right_wheel_joint" type="continuous">
    <parent link="base_link"/>
    <child link="rear_right_wheel"/>
    <origin xyz="-0.2 -0.2 0" rpy="${pi/2} 0 0"/>
    <axis xyz="0 0 -1"/>
</joint>

<link name="rear_right_wheel">
    <visual>
        <geometry>
            <cylinder radius="0.05" length="0.04"/>
        </geometry>
        <material name="blue"/>
    </visual>
</link>

<!-- Front Left Wheel -->

<joint name="front_left_wheel_joint" type="continuous">
    <parent link="base_link"/>
    <child link="front_left_wheel"/>
    <origin xyz="0.2 0.2 0" rpy="-${pi/2} 0 0"/>
    <axis xyz="0 0 1"/>
</joint>

<link name="front_left_wheel">
    <visual>
        <geometry>
            <cylinder radius="0.05" length="0.04"/>
        </geometry>
        <material name="blue"/>
    </visual>
</link>

<!-- Front Right Wheel -->

<joint name="front_right_wheel_joint" type="continuous">
    <parent link="base_link"/>
    <child link="front_right_wheel"/>
    <origin xyz="0.2 -0.2 0" rpy="${pi/2} 0 0"/>
    <axis xyz="0 0 -1"/>
</joint>

<link name="front_right_wheel">
    <visual>
        <geometry>
            <cylinder radius="0.05" length="0.04"/>
        </geometry>
        <material name="blue"/>
    </visual>
</link>

</robot>
